Workbook

Sheet Stat Formulas
A1: Name | B1: Stat ID | C1: Description | D1: Formula (abbreviated) | E1: Base Value (0) | F1: Primary Stat Dependencies | G1: Direct Stat Dependencies | H1: Full Stat Dependency Chain | I1: Base (10) | J1: Human (12) | K1: Minor Racial (13) | L1: Major Racial (14) | M1: Max Base (50) | N1: Max Human (52) | O1: Max Minor Racial (53) | P1: Max Major Racial (54) | Q1: Show at Char Creation | R1: Formula (raw) | S1: Type
A2: Arcane Resistance Multiplier | B2: ArcaneResistanceMultiplier | C2: Multiplier for arcane damage from resistance | D2: 1 - ArcaneResistanceValue | E2: 1 | G2: Arcane Resistance | H2: Arcane Resistance | I2: 1 | J2: 1 | K2: 1 | L2: 1 | M2: 1 | N2: 1 | O2: 1 | P2: 1 | Q2: Yes | R2: 1 - Ctx.GetOrCalculateStat(Stat.ArcaneResistanceValue) | S2: Derived
A3: Base Faith Regeneration | B3: BaseFaithRegeneration | C3: Base Faith Regeneration from Spirit and flat sources | D3: 10 | E3: 10 | I3: 10 | J3: 10 | K3: 10 | L3: 10 | M3: 10 | N3: 10 | O3: 10 | P3: 10 | Q3: Yes | R3: 10 | S3: Derived
A4: Base Health Regeneration | B4: BaseHealthRegeneration | C4: Base Health Regeneration from Vitality and flat sources | D4: MaxHP / 150 | E4: 33.333333 | F4: Vitality | G4: Maximum Health | H4: Base Maximum Health, Maximum Health, Maximum Health Increase | I4: 48 | J4: 51.253333 | K4: 52.92 | L4: 54.613333 | M4: 133.33333 | N4: 138.72 | O4: 141.45333 | P4: 144.21333 | Q4: Yes | R4: Ctx.GetOrCalculateStat(Stat.MaxHP) / 150 | S4: Derived
A5: Base Mana Regeneration | B5: BaseManaRegeneration | C5: Base Mana Regeneration from Spirit and flat sources | D5: MaxMana / 500 | E5: 10 | F5: Spirit | G5: Max Mana | H5: Base Maximum Mana, Max Mana, Maximum Mana Increase | I5: 14.4 | J5: 15.376 | K5: 15.876 | L5: 16.384 | M5: 40 | N5: 41.616 | O5: 42.436 | P5: 43.264 | Q5: Yes | R5: Ctx.GetOrCalculateStat(Stat.MaxMana) / 500 | S5: Derived
A6: Base Maximum Health | B6: BaseMaxHP | C6: Base Maximum Health from Vitality and flat sources | D6: 5000 + 100 * Vitality | E6: 5000 | F6: Vitality | I6: 6000 | J6: 6200 | K6: 6300 | L6: 6400 | M6: 10000 | N6: 10200 | O6: 10300 | P6: 10400 | Q6: Yes | R6: 5000 + 100 * Ctx.GetOrCalculateStat(Stat.Vitality) | S6: Derived
A7: Base Maximum Mana | B7: BaseMaxMana | C7: Base Maximum Mana from Spirit and flat sources | D7: 5000 + 100 * Spirit | E7: 5000 | F7: Spirit | I7: 6000 | J7: 6200 | K7: 6300 | L7: 6400 | M7: 10000 | N7: 10200 | O7: 10300 | P7: 10400 | Q7: Yes | R7: 5000 + 100 * Ctx.GetOrCalculateStat(Stat.Spirit) | S7: Derived
A8: Buff Duration | B8: BuffDurationMultiplier | C8: Increases the duration of Buffs you apply | D8: (1 + Conviction * 0.005) | E8: 1 | F8: Conviction | I8: 1.05 | J8: 1.06 | K8: 1.065 | L8: 1.07 | M8: 1.25 | N8: 1.26 | O8: 1.265 | P8: 1.27 | Q8: Yes | R8: (float) (1 + Ctx.GetOrCalculateStat(Stat.Conviction) * 0.005) | S8: Derived
A9: Buff Effect | B9: BuffEffectMultiplier | C9: Increases the numerical values of Buffs you apply | D9: (1 + Conviction * 0.005) | E9: 1 | F9: Conviction | I9: 1.05 | J9: 1.06 | K9: 1.065 | L9: 1.07 | M9: 1.25 | N9: 1.26 | O9: 1.265 | P9: 1.27 | Q9: Yes | R9: (float) (1 + Ctx.GetOrCalculateStat(Stat.Conviction) * 0.005) | S9: Derived
A10: Chaos Resistance Multiplier | B10: ChaosResistanceMultiplier | C10: Multiplier for chaos damage from resistance | D10: 1 - ChaosResistanceValue | E10: 1 | G10: Chaos Resistance | H10: Chaos Resistance | I10: 1 | J10: 1 | K10: 1 | L10: 1 | M10: 1 | N10: 1 | O10: 1 | P10: 1 | Q10: Yes | R10: 1 - Ctx.GetOrCalculateStat(Stat.ChaosResistanceValue) | S10: Derived
A11: Critical Hit Chance | B11: CriticalHitChance | C11: Fraction chance for critical hits | D11: (2 * (1 / (1 + Exp(-0.011 * CriticalHitRating))) - 1) | E11: 0.054945 | G11: Critical Hit Rating | H11: Critical Hit Rating | I11: 0.054945 | J11: 0.054945 | K11: 0.054945 | L11: 0.054945 | M11: 0.054945 | N11: 0.054945 | O11: 0.054945 | P11: 0.054945 | Q11: Yes | R11: (float) (2 * (1 / (1 + System.Math.Exp(-0.011 * Ctx.GetOrCalculateStat(Stat.CriticalHitRating)))) - 1) | S11: Derived
A12: Crushing Resistance Multiplier | B12: CrushingResistanceMultiplier | C12: Multiplier for crushing damage from resistance | D12: 1 - CrushingResistanceValue | E12: 1 | G12: Crushing Resistance | H12: Crushing Resistance | I12: 1 | J12: 1 | K12: 1 | L12: 1 | M12: 1 | N12: 1 | O12: 1 | P12: 1 | Q12: Yes | R12: 1 - Ctx.GetOrCalculateStat(Stat.CrushingResistanceValue) | S12: Derived
A13: Current Max Health | B13: MaxHPLimit | C13: Restricted Max HP for limitations like Wounds | D13: MaxHP | E13: 5000 | F13: Vitality | G13: Maximum Health | H13: Base Maximum Health, Maximum Health, Maximum Health Increase | I13: 7200 | J13: 7688 | K13: 7938 | L13: 8192 | M13: 20000 | N13: 20808 | O13: 21218 | P13: 21632 | Q13: Yes | R13: Ctx.GetOrCalculateStat(Stat.MaxHP) | S13: Derived
A14: Debuff Duration Multiplier | B14: DebuffDurationMultiplier | C14: Multiplier for duration of Debuffs applied to you | D14: 1 - DebuffDurationReduction | E14: 1 | F14: Endurance | G14: Debuff Duration Reduction | H14: Debuff Duration Reduction | I14: 0.95 | J14: 0.94 | K14: 0.935 | L14: 0.93 | M14: 0.75 | N14: 0.74 | O14: 0.735 | P14: 0.73 | Q14: Yes | R14: 1 - Ctx.GetOrCalculateStat(Stat.DebuffDurationReduction) | S14: Derived
A15: Debuff Duration Reduction | B15: DebuffDurationReduction | C15: Reduces the duration of Debuffs applied to you | D15: (Endurance * 0.005) | E15: 0 | F15: Endurance | I15: 0.05 | J15: 0.06 | K15: 0.065 | L15: 0.07 | M15: 0.25 | N15: 0.26 | O15: 0.265 | P15: 0.27 | Q15: Yes | R15: (float) (Ctx.GetOrCalculateStat(Stat.Endurance) * 0.005) | S15: Derived
A16: Detection Range | B16: DetectionRange | C16: Determines how far away you can see Stealthed enemies. | D16: (5 + Command * 0.75) | E16: 5 | F16: Command | I16: 12.5 | J16: 14 | K16: 14.75 | L16: 15.5 | M16: 42.5 | N16: 44 | O16: 44.75 | P16: 45.5 | Q16: Yes | R16: (float) (5 + Ctx.GetOrCalculateStat(Stat.Command) * 0.75) | S16: Derived
A17: Detection Regen | B17: DetectionRegen | C17: Regen to make Detection Resource work | D17: 100 | E17: 100 | I17: 100 | J17: 100 | K17: 100 | L17: 100 | M17: 100 | N17: 100 | O17: 100 | P17: 100 | Q17: Yes | R17: 100 | S17: Derived
A18: Earth Resistance Multiplier | B18: EarthResistanceMultiplier | C18: Multiplier for earth damage from resistance | D18: 1 - EarthResistanceValue | E18: 1 | G18: Earth Resistance | H18: Earth Resistance | I18: 1 | J18: 1 | K18: 1 | L18: 1 | M18: 1 | N18: 1 | O18: 1 | P18: 1 | Q18: Yes | R18: 1 - Ctx.GetOrCalculateStat(Stat.EarthResistanceValue) | S18: Derived
A19: Faith Regeneration Increase | B19: FaithRegenerationIncrease | C19: Multiplier on Base Faith Regeneration | D19: (Spirit * 0.03) | E19: 0 | F19: Spirit | I19: 0.3 | J19: 0.36 | K19: 0.39 | L19: 0.42 | M19: 1.5 | N19: 1.56 | O19: 1.59 | P19: 1.62 | Q19: Yes | R19: (float) (Ctx.GetOrCalculateStat(Stat.Spirit) * 0.03) | S19: Derived
A20: Fire Resistance Multiplier | B20: FireResistanceMultiplier | C20: Multiplier for fire damage from resistance | D20: 1 - FireResistanceValue | E20: 1 | G20: Fire Resistance | H20: Fire Resistance | I20: 1 | J20: 1 | K20: 1 | L20: 1 | M20: 1 | N20: 1 | O20: 1 | P20: 1 | Q20: Yes | R20: 1 - Ctx.GetOrCalculateStat(Stat.FireResistanceValue) | S20: Derived
A21: Focus Charger Regen | B21: FocusChargerRegen | C21: Amount to increase focus charger bar per tick | D21: 20 | E21: 20 | I21: 20 | J21: 20 | K21: 20 | L21: 20 | M21: 20 | N21: 20 | O21: 20 | P21: 20 | Q21: Yes | R21: 20 | S21: Derived
A22: Healing Multiplier | B22: BaseHealingMultiplier | C22: Increases Healing done by your abilities | D22: (1 + Conviction * 0.01) | E22: 1 | F22: Conviction | I22: 1.1 | J22: 1.12 | K22: 1.13 | L22: 1.14 | M22: 1.5 | N22: 1.52 | O22: 1.53 | P22: 1.54 | Q22: Yes | R22: (float) (1 + Ctx.GetOrCalculateStat(Stat.Conviction) * 0.01) | S22: Derived
A23: Health Regeneration | B23: CombinedHealthRegeneration | C23: Rate at which combined health regenerates over time. | D23: HealthRegeneration | E23: 33.333333 | F23: Vitality | G23: Health Regeneration | H23: Base Health Regeneration, Base Maximum Health, Health Regeneration, Health Regeneration Increase, Maximum Health, Maximum Health Increase | I23: 57.6 | J23: 63.554133 | K23: 66.6792 | L23: 69.905067 | M23: 266.66667 | N23: 282.9888 | O23: 291.39387 | P23: 299.96373 | Q23: Yes | R23: Ctx.GetOrCalculateStat(Stat.HealthRegeneration) | S23: Derived
A24: Health Regeneration | B24: HealthRegeneration | C24: Health regenerated per second while out of combat. | D24: (BaseHealthRegeneration * (1 + HealthRegenerationIncrease)) | E24: 33.333333 | F24: Vitality | G24: Base Health Regeneration, Health Regeneration Increase | H24: Base Health Regeneration, Base Maximum Health, Health Regeneration Increase, Maximum Health, Maximum Health Increase | I24: 57.6 | J24: 63.554133 | K24: 66.6792 | L24: 69.905067 | M24: 266.66667 | N24: 282.9888 | O24: 291.39387 | P24: 299.96373 | Q24: Yes | R24: (float) (Ctx.GetOrCalculateStat(Stat.BaseHealthRegeneration) * (1 + Ctx.GetOrCalculateStat(Stat.HealthRegenerationIncrease))) | S24: Derived
A25: Health Regeneration Increase | B25: HealthRegenerationIncrease | C25: Multiplier on Base Health Regeneration | D25: (Vitality * 0.02) | E25: 0 | F25: Vitality | I25: 0.2 | J25: 0.24 | K25: 0.26 | L25: 0.28 | M25: 1 | N25: 1.04 | O25: 1.06 | P25: 1.08 | Q25: Yes | R25: (float) (Ctx.GetOrCalculateStat(Stat.Vitality) * 0.02) | S25: Derived
A26: Lightning Resistance Multiplier | B26: LightningResistanceMultiplier | C26: Multiplier for lightning damage from resistance | D26: 1 - LightningResistanceValue | E26: 1 | G26: Lightning Resistance | H26: Lightning Resistance | I26: 1 | J26: 1 | K26: 1 | L26: 1 | M26: 1 | N26: 1 | O26: 1 | P26: 1 | Q26: Yes | R26: 1 - Ctx.GetOrCalculateStat(Stat.LightningResistanceValue) | S26: Derived
A27: Magic Armor Multiplier | B27: MagicArmorMultiplier | C27: Multiplier for magic damage from armor | D27: 1 - (0.003 * MagicArmorRating) / (1 + 0.003 * MagicArmorRating) | E27: 1 | G27: Magic Armor Rating | H27: Magic Armor Rating | I27: 1 | J27: 1 | K27: 1 | L27: 1 | M27: 1 | N27: 1 | O27: 1 | P27: 1 | Q27: Yes | R27: 1 - (0.003f * Ctx.GetOrCalculateStat(Stat.MagicArmorRating)) / (1 + 0.003f * Ctx.GetOrCalculateStat(Stat.MagicArmorRating)) | S27: Derived
A28: Mana Regeneration Increase | B28: ManaRegenerationIncrease | C28: Multiplier on Base Mana Regeneration | D28: (Spirit * 0.02) | E28: 0 | F28: Spirit | I28: 0.2 | J28: 0.24 | K28: 0.26 | L28: 0.28 | M28: 1 | N28: 1.04 | O28: 1.06 | P28: 1.08 | Q28: Yes | R28: (float) (Ctx.GetOrCalculateStat(Stat.Spirit) * 0.02) | S28: Derived
A29: Maximum Combined Health | B29: MaxCombinedHealth | C29: Maximum HP + maximum shield | D29: MaxHP + MaxShield | E29: 7500 | F29: Vitality | G29: Maximum Health, Maximum Shield | H29: Base Maximum Health, Maximum Health, Maximum Health Increase, Maximum Shield | I29: 10800 | J29: 11532 | K29: 11907 | L29: 12288 | M29: 30000 | N29: 31212 | O29: 31827 | P29: 32448 | Q29: Yes | R29: Ctx.GetOrCalculateStat(Stat.MaxHP) + Ctx.GetOrCalculateStat(Stat.MaxShield) | S29: Derived
A30: Maximum Health | B30: MaxHP | C30: Maximum Health value | D30: (BaseMaxHP * (1 + MaxHPIncrease)) | E30: 5000 | F30: Vitality | G30: Base Maximum Health, Maximum Health Increase | H30: Base Maximum Health, Maximum Health Increase | I30: 7200 | J30: 7688 | K30: 7938 | L30: 8192 | M30: 20000 | N30: 20808 | O30: 21218 | P30: 21632 | Q30: Yes | R30: (float) (Ctx.GetOrCalculateStat(Stat.BaseMaxHP) * (1 + Ctx.GetOrCalculateStat(Stat.MaxHPIncrease))) | S30: Derived
A31: Maximum Health Increase | B31: MaxHPIncrease | C31: Multiplier on Base Maximum Health | D31: (Vitality * 0.02) | E31: 0 | F31: Vitality | I31: 0.2 | J31: 0.24 | K31: 0.26 | L31: 0.28 | M31: 1 | N31: 1.04 | O31: 1.06 | P31: 1.08 | Q31: Yes | R31: (float) (Ctx.GetOrCalculateStat(Stat.Vitality) * 0.02) | S31: Derived
A32: Maximum Mana Increase | B32: MaxManaIncrease | C32: Multiplier on Base Maximum Mana | D32: (Spirit * 0.02) | E32: 0 | F32: Spirit | I32: 0.2 | J32: 0.24 | K32: 0.26 | L32: 0.28 | M32: 1 | N32: 1.04 | O32: 1.06 | P32: 1.08 | Q32: Yes | R32: (float) (Ctx.GetOrCalculateStat(Stat.Spirit) * 0.02) | S32: Derived
A33: Maximum Panic Rating | B33: MaxPanic | C33: The maximum amount of Panic you can sustain before becoming vulnerable to Terror effects. | D33: 1000 | E33: 1000 | I33: 1000 | J33: 1000 | K33: 1000 | L33: 1000 | M33: 1000 | N33: 1000 | O33: 1000 | P33: 1000 | Q33: Yes | R33: 1000 | S33: Derived
A34: Maximum Prospecting Excavation | B34: ProspectingExcavationMax | C34: Maximum excavation of prospecting resource | D34: 100 | E34: 100 | I34: 100 | J34: 100 | K34: 100 | L34: 100 | M34: 100 | N34: 100 | O34: 100 | P34: 100 | Q34: Yes | R34: 100 | S34: Derived
A35: Maximum Prospecting Fragility | B35: ProspectingFragilityMax | C35: Maximum fragility of prospecting resource | D35: 100 | E35: 100 | I35: 100 | J35: 100 | K35: 100 | L35: 100 | M35: 100 | N35: 100 | O35: 100 | P35: 100 | Q35: Yes | R35: 100 | S35: Derived
A36: Maximum Shield | B36: MaxShield | C36: Increases the character's maximum shield value. | D36: MaxHP / 2 | E36: 2500 | F36: Vitality | G36: Maximum Health | H36: Base Maximum Health, Maximum Health, Maximum Health Increase | I36: 3600 | J36: 3844 | K36: 3969 | L36: 4096 | M36: 10000 | N36: 10404 | O36: 10609 | P36: 10816 | Q36: Yes | R36: Ctx.GetOrCalculateStat(Stat.MaxHP) / 2 | S36: Derived
A37: Mind Resistance Multiplier | B37: MindResistanceMultiplier | C37: Multiplier for mind damage from resistance | D37: 1 - MindResistanceValue | E37: 1 | G37: Mind Resistance | H37: Mind Resistance | I37: 1 | J37: 1 | K37: 1 | L37: 1 | M37: 1 | N37: 1 | O37: 1 | P37: 1 | Q37: Yes | R37: 1 - Ctx.GetOrCalculateStat(Stat.MindResistanceValue) | S37: Derived
A38: Movement Speed | B38: MaxMoveSpeed | C38: Increases the maximum movement speed of the character. | D38: 11 | E38: 11 | I38: 11 | J38: 11 | K38: 11 | L38: 11 | M38: 11 | N38: 11 | O38: 11 | P38: 11 | Q38: Yes | R38: 11 | S38: Derived
A39: Panic Multiplier | B39: BasePanicMultiplier | C39: Increases Panic inflicted by your abilities | D39: (1 + Command * 0.01) | E39: 1 | F39: Command | I39: 1.1 | J39: 1.12 | K39: 1.13 | L39: 1.14 | M39: 1.5 | N39: 1.52 | O39: 1.53 | P39: 1.54 | Q39: Yes | R39: (float) (1 + Ctx.GetOrCalculateStat(Stat.Command) * 0.01) | S39: Derived
A40: Panic Rating Decay | B40: PanicDecay | C40: Increase the rate at which accumulated Panic is decreased. | D40: -5 | E40: -5 | I40: -5 | J40: -5 | K40: -5 | L40: -5 | M40: -5 | N40: -5 | O40: -5 | P40: -5 | Q40: Yes | R40: -5 | S40: Derived
...

Sheet Race Data
A1: Race ID | B1: Display Name | C1: Faction | D1: Attunement | E1: Command | F1: Conviction | G1: Dexterity | H1: Endurance | I1: Spirit | J1: Strength | K1: Vitality | L1: Will
A2: CaitSith | B2: Cait Sith (Arthurian) | C2: Arthurian | D2: 0 | E2: 0 | F2: 0 | G2: 0 | H2: 0 | I2: 0 | J2: 0 | K2: 0 | L2: 0
A3: Dvergr | B3: Dvergr (Viking) | C3: Viking | D3: 0 | E3: 0 | F3: 0 | G3: 0 | H3: 0 | I3: 0 | J3: 0 | K3: 4 | L3: 3
A4: Firbog | B4: Firbog (TDD) | C4: TDD | D4: 0 | E4: 0 | F4: 0 | G4: 0 | H4: 3 | I4: 4 | J4: 0 | K4: 0 | L4: 0
A5: Golem | B5: Golem (Arthurian) | C5: Arthurian | D5: 0 | E5: 0 | F5: 3 | G5: 0 | H5: 4 | I5: 0 | J5: 0 | K5: 0 | L5: 0
A6: Hamadryad | B6: Hamadryad (TDD) | C6: TDD | D6: 0 | E6: 0 | F6: 0 | G6: 0 | H6: 0 | I6: 0 | J6: 0 | K6: 0 | L6: 0
A7: HumanMaleA | B7: HumanMaleA (Arthurian) | C7: Arthurian | D7: 2 | E7: 2 | F7: 2 | G7: 2 | H7: 2 | I7: 2 | J7: 2 | K7: 2 | L7: 2
A8: HumanMaleT | B8: HumanMaleT (TDD) | C8: TDD | D8: 2 | E8: 2 | F8: 2 | G8: 2 | H8: 2 | I8: 2 | J8: 2 | K8: 2 | L8: 2
A9: HumanMaleV | B9: HumanMaleV (Viking) | C9: Viking | D9: 2 | E9: 2 | F9: 2 | G9: 2 | H9: 2 | I9: 2 | J9: 2 | K9: 2 | L9: 2
A10: Jotnar | B10: Jotnar (Viking) | C10: Viking | D10: 0 | E10: 0 | F10: 0 | G10: 0 | H10: 3 | I10: 0 | J10: 4 | K10: 0 | L10: 0
A11: Luchorpan | B11: Luchorpan (TDD) | C11: TDD | D11: 0 | E11: 0 | F11: 3 | G11: 4 | H11: 0 | I11: 0 | J11: 0 | K11: 0 | L11: 0
A12: Pict | B12: Pict (Arthurian) | C12: Arthurian | D12: 0 | E12: 0 | F12: 0 | G12: 0 | H12: 0 | I12: 0 | J12: 0 | K12: 0 | L12: 0
A13: Strm | B13: St'rm (Arthurian) | C13: Arthurian | D13: 0 | E13: 0 | F13: 0 | G13: 0 | H13: 0 | I13: 0 | J13: 0 | K13: 0 | L13: 0
... A15: Valkyrie | B15: Valkyrie (Viking) | C15: Viking | D15: 0 | E15: 0 | F15: 0 | G15: 0 | H15: 0 | I15: 0 | J15: 0 | K15: 0 | L15: 0

Sheet Creation Calculator
A1: CU Character Stat Calculator
A2: Race | B2: Cait Sith (Arthurian)
A3: Points Allocated | C3: =SUM(C6:C14) -> 0 | D3: Points Remaining | E3: =130-C3 -> 130
A5: Stat | B5: Base | C5: Allocated | D5: Racial Bonus | E5: Total
A6: Attunement | B6: 10 | C6: 0 | D6: =IFERROR(SUMPRODUCT(('Race Data'!B$2:B$50=B$2)*('Race Data'!D$2:D$50)),0) -> 0 | E6: =B6+C6+D6 -> 10
A7: Command | B7: 10 | C7: 0 | D7: =IFERROR(SUMPRODUCT(('Race Data'!B$2:B$50=B$2)*('Race Data'!E$2:E$50)),0) -> 0 | E7: =B7+C7+D7 -> 10
A8: Conviction | B8: 10 | C8: 0 | D8: =IFERROR(SUMPRODUCT(('Race Data'!B$2:B$50=B$2)*('Race Data'!F$2:F$50)),0) -> 0 | E8: =B8+C8+D8 -> 10
A9: Dexterity | B9: 10 | C9: 0 | D9: =IFERROR(SUMPRODUCT(('Race Data'!B$2:B$50=B$2)*('Race Data'!G$2:G$50)),0) -> 0 | E9: =B9+C9+D9 -> 10
A10: Endurance | B10: 10 | C10: 0 | D10: =IFERROR(SUMPRODUCT(('Race Data'!B$2:B$50=B$2)*('Race Data'!H$2:H$50)),0) -> 0 | E10: =B10+C10+D10 -> 10
A11: Spirit | B11: 10 | C11: 0 | D11: =IFERROR(SUMPRODUCT(('Race Data'!B$2:B$50=B$2)*('Race Data'!I$2:I$50)),0) -> 0 | E11: =B11+C11+D11 -> 10
A12: Strength | B12: 10 | C12: 0 | D12: =IFERROR(SUMPRODUCT(('Race Data'!B$2:B$50=B$2)*('Race Data'!J$2:J$50)),0) -> 0 | E12: =B12+C12+D12 -> 10
A13: Vitality | B13: 10 | C13: 0 | D13: =IFERROR(SUMPRODUCT(('Race Data'!B$2:B$50=B$2)*('Race Data'!K$2:K$50)),0) -> 0 | E13: =B13+C13+D13 -> 10
A14: Will | B14: 10 | C14: 0 | D14: =IFERROR(SUMPRODUCT(('Race Data'!B$2:B$50=B$2)*('Race Data'!L$2:L$50)),0) -> 0 | E14: =B14+C14+D14 -> 10
A16: Stat Name | B16: Stat ID | C16: Type | D16: Abbreviated Formula | E16: Value
A17: Spirit | B17: Spirit | C17: Primary | D17: 0 | E17: =E11 -> 10
A18: Faith Regeneration Increase | B18: FaithRegenerationIncrease | C18: Derived | D18: (Spirit * 0.03) | E18: =(E11 * 0.03) -> 0.3
A19: Attunement | B19: Attunement | C19: Primary | D19: 0 | E19: =E6 -> 10
A20: Endurance | B20: Endurance | C20: Primary | D20: 0 | E20: =E10 -> 10
A21: Guts Threshold Increase | B21: GutsThresholdIncrease | C21: Hidden | D21: (Endurance * 0.01) | E21: =(E10 * 0.01) -> 0.1
A22: Maximum Prospecting Fragility | B22: ProspectingFragilityMax | C22: Derived | D22: 100 | E22: =100 -> 100
A23: Shadow Resistance | B23: ShadowResistanceValue | C23: Hidden | D23: 0 | E23: =0 -> 0
A24: Size Modifier | B24: SizeModifier | C24: Hidden | E24: =
A25: Panic Rating Decay | B25: PanicDecay | C25: Derived | D25: -5 | E25: =-5 -> -5
A26: Spirit Resistance | B26: SpiritResistanceValue | C26: Hidden | D26: 0 | E26: =0 -> 0
A27: Spirit Resistance Multiplier | B27: SpiritResistanceMultiplier | C27: Derived | D27: 1 - SpiritResistanceValue | E27: =1 - E26 -> 1
A28: Vitality | B28: Vitality | C28: Primary | D28: 0 | E28: =E13 -> 10
A29: Base Maximum Health | B29: BaseMaxHP | C29: Derived | D29: 5000 + 100 * Vitality | E29: =5000 + 100 * E13 -> 6000
A30: Maximum Health Increase | B30: MaxHPIncrease | C30: Derived | D30: (Vitality * 0.02) | E30: =(E13 * 0.02) -> 0.2
A31: Maximum Health | B31: MaxHP | C31: Derived | D31: (BaseMaxHP * (1 + MaxHPIncrease)) | E31: =(E29 * (1 + E30)) -> 7200
A32: Maximum Shield | B32: MaxShield | C32: Derived | D32: MaxHP / 2 | E32: =E31 / 2 -> 3600
A33: Maximum Combined Health | B33: MaxCombinedHealth | C33: Derived | D33: MaxHP + MaxShield | E33: =E31 + E32 -> 10800
A34: StatName_ControlRegenViking | B34: ControlRegenViking | C34: Hidden | E34: =
A35: Conviction | B35: Conviction | C35: Primary | D35: 0 | E35: =E8 -> 10
A36: Buff Duration | B36: BuffDurationMultiplier | C36: Derived | D36: (1 + Conviction * 0.005) | E36: =(1 + E8 * 0.005) -> 1.05
A37: Critical Hit Multiplier | B37: CriticalDamageMultiplier | C37: Hidden | D37: 1.25 | E37: =1.25 -> 1.25
A38: Percent Max | B38: PercentMax | C38: Derived | D38: 100 | E38: =100 -> 100
A39: Health Regeneration Increase | B39: HealthRegenerationIncrease | C39: Derived | D39: (Vitality * 0.02) | E39: =(E13 * 0.02) -> 0.2
A40: Base Health Regeneration | B40: BaseHealthRegeneration | C40: Derived | D40: MaxHP / 150 | E40: =E31 / 150 -> 48
A41: Health Regeneration | B41: HealthRegeneration | C41: Derived | D41: (BaseHealthRegeneration * (1 + HealthRegenerationIncrease)) | E41: =(E40 * (1 + E39)) -> 57.6
A42: Health Regeneration | B42: CombinedHealthRegeneration | C42: Derived | D42: HealthRegeneration | E42: =E41 -> 57.6
...

Sheet Gear Calculator
A1: CU Character Stat Calculator (with Gear)
A2: Race | B2: Cait Sith (Arthurian)
A3: Points Allocated | C3: =SUM(C6:C14) -> 0 | D3: Points Remaining | E3: =130-C3 -> 130
A5: Stat | B5: Base | C5: Allocated | D5: Racial Bonus | E5: Gear Bonus | F5: Total
A6: Attunement | B6: 10 | C6: 0 | D6: =IFERROR(SUMPRODUCT(('Race Data'!B$2:B$50=B$2)*('Race Data'!D$2:D$50)),0) -> 0 | E6: =SUM(C18:C29) -> 0 | F6: =B6+C6+D6+E6 -> 10
A7: Command | B7: 10 | C7: 0 | D7: =IFERROR(SUMPRODUCT(('Race Data'!B$2:B$50=B$2)*('Race Data'!E$2:E$50)),0) -> 0 | E7: =SUM(D18:D29) -> 0 | F7: =B7+C7+D7+E7 -> 10
A8: Conviction | B8: 10 | C8: 0 | D8: =IFERROR(SUMPRODUCT(('Race Data'!B$2:B$50=B$2)*('Race Data'!F$2:F$50)),0) -> 0 | E8: =SUM(E18:E29) -> 0 | F8: =B8+C8+D8+E8 -> 10
A9: Dexterity | B9: 10 | C9: 0 | D9: =IFERROR(SUMPRODUCT(('Race Data'!B$2:B$50=B$2)*('Race Data'!G$2:G$50)),0) -> 0 | E9: =SUM(F18:F29) -> 0 | F9: =B9+C9+D9+E9 -> 10
A10: Endurance | B10: 10 | C10: 0 | D10: =IFERROR(SUMPRODUCT(('Race Data'!B$2:B$50=B$2)*('Race Data'!H$2:H$50)),0) -> 0 | E10: =SUM(G18:G29) -> 0 | F10: =B10+C10+D10+E10 -> 10
A11: Spirit | B11: 10 | C11: 0 | D11: =IFERROR(SUMPRODUCT(('Race Data'!B$2:B$50=B$2)*('Race Data'!I$2:I$50)),0) -> 0 | E11: =SUM(H18:H29) -> 0 | F11: =B11+C11+D11+E11 -> 10
A12: Strength | B12: 10 | C12: 0 | D12: =IFERROR(SUMPRODUCT(('Race Data'!B$2:B$50=B$2)*('Race Data'!J$2:J$50)),0) -> 0 | E12: =SUM(I18:I29) -> 0 | F12: =B12+C12+D12+E12 -> 10
A13: Vitality | B13: 10 | C13: 0 | D13: =IFERROR(SUMPRODUCT(('Race Data'!B$2:B$50=B$2)*('Race Data'!K$2:K$50)),0) -> 0 | E13: =SUM(J18:J29) -> 0 | F13: =B13+C13+D13+E13 -> 10
A14: Will | B14: 10 | C14: 0 | D14: =IFERROR(SUMPRODUCT(('Race Data'!B$2:B$50=B$2)*('Race Data'!L$2:L$50)),0) -> 0 | E14: =SUM(K18:K29) -> 0 | F14: =B14+C14+D14+E14 -> 10
A16: Gear Slot Bonuses
A17: Gear Slot | B17: Item Name | C17: Attunement | D17: Command | E17: Conviction | F17: Dexterity | G17: Endurance | H17: Spirit | I17: Strength | J17: Vitality | K17: Will | L17: Physical Armor Rating | M17: Magic Armor Rating | N17: Weapon Damage | O17: Critical Hit Rating | P17: Critical Hit Multiplier | Q17: Arcane Resistance | R17: Chaos Resistance | S17: Crushing Resistance | T17: Earth Resistance | U17: Fire Resistance | V17: Lightning Resistance | W17: Mind Resistance | X17: Piercing Resistance | Y17: Shadow Resistance | Z17: Slashing Resistance | AA17: Spirit Resistance | AB17: Void Resistance
A18: Head | C18: 0 | D18: 0 | E18: 0 | F18: 0 | G18: 0 | H18: 0 | I18: 0 | J18: 0 | K18: 0 | L18: 0 | M18: 0 | N18: 0 | O18: 0 | P18: 0 | Q18: 0 | R18: 0 | S18: 0 | T18: 0 | U18: 0 | V18: 0 | W18: 0 | X18: 0 | Y18: 0 | Z18: 0 | AA18: 0 | AB18: 0
A19: Chest | C19: 0 | D19: 0 | E19: 0 | F19: 0 | G19: 0 | H19: 0 | I19: 0 | J19: 0 | K19: 0 | L19: 0 | M19: 0 | N19: 0 | O19: 0 | P19: 0 | Q19: 0 | R19: 0 | S19: 0 | T19: 0 | U19: 0 | V19: 0 | W19: 0 | X19: 0 | Y19: 0 | Z19: 0 | AA19: 0 | AB19: 0
A20: Hands | C20: 0 | D20: 0 | E20: 0 | F20: 0 | G20: 0 | H20: 0 | I20: 0 | J20: 0 | K20: 0 | L20: 0 | M20: 0 | N20: 0 | O20: 0 | P20: 0 | Q20: 0 | R20: 0 | S20: 0 | T20: 0 | U20: 0 | V20: 0 | W20: 0 | X20: 0 | Y20: 0 | Z20: 0 | AA20: 0 | AB20: 0
A21: Legs | C21: 0 | D21: 0 | E21: 0 | F21: 0 | G21: 0 | H21: 0 | I21: 0 | J21: 0 | K21: 0 | L21: 0 | M21: 0 | N21: 0 | O21: 0 | P21: 0 | Q21: 0 | R21: 0 | S21: 0 | T21: 0 | U21: 0 | V21: 0 | W21: 0 | X21: 0 | Y21: 0 | Z21: 0 | AA21: 0 | AB21: 0
A22: Feet | C22: 0 | D22: 0 | E22: 0 | F22: 0 | G22: 0 | H22: 0 | I22: 0 | J22: 0 | K22: 0 | L22: 0 | M22: 0 | N22: 0 | O22: 0 | P22: 0 | Q22: 0 | R22: 0 | S22: 0 | T22: 0 | U22: 0 | V22: 0 | W22: 0 | X22: 0 | Y22: 0 | Z22: 0 | AA22: 0 | AB22: 0
A23: Back | C23: 0 | D23: 0 | E23: 0 | F23: 0 | G23: 0 | H23: 0 | I23: 0 | J23: 0 | K23: 0 | L23: 0 | M23: 0 | N23: 0 | O23: 0 | P23: 0 | Q23: 0 | R23: 0 | S23: 0 | T23: 0 | U23: 0 | V23: 0 | W23: 0 | X23: 0 | Y23: 0 | Z23: 0 | AA23: 0 | AB23: 0
A24: Primary Weapon | C24: 0 | D24: 0 | E24: 0 | F24: 0 | G24: 0 | H24: 0 | I24: 0 | J24: 0 | K24: 0 | L24: 0 | M24: 0 | N24: 0 | O24: 0 | P24: 0 | Q24: 0 | R24: 0 | S24: 0 | T24: 0 | U24: 0 | V24: 0 | W24: 0 | X24: 0 | Y24: 0 | Z24: 0 | AA24: 0 | AB24: 0
A25: Secondary Weapon | C25: 0 | D25: 0 | E25: 0 | F25: 0 | G25: 0 | H25: 0 | I25: 0 | J25: 0 | K25: 0 | L25: 0 | M25: 0 | N25: 0 | O25: 0 | P25: 0 | Q25: 0 | R25: 0 | S25: 0 | T25: 0 | U25: 0 | V25: 0 | W25: 0 | X25: 0 | Y25: 0 | Z25: 0 | AA25: 0 | AB25: 0
A26: Waist | C26: 0 | D26: 0 | E26: 0 | F26: 0 | G26: 0 | H26: 0 | I26: 0 | J26: 0 | K26: 0 | L26: 0 | M26: 0 | N26: 0 | O26: 0 | P26: 0 | Q26: 0 | R26: 0 | S26: 0 | T26: 0 | U26: 0 | V26: 0 | W26: 0 | X26: 0 | Y26: 0 | Z26: 0 | AA26: 0 | AB26: 0
A27: Neck | C27: 0 | D27: 0 | E27: 0 | F27: 0 | G27: 0 | H27: 0 | I27: 0 | J27: 0 | K27: 0 | L27: 0 | M27: 0 | N27: 0 | O27: 0 | P27: 0 | Q27: 0 | R27: 0 | S27: 0 | T27: 0 | U27: 0 | V27: 0 | W27: 0 | X27: 0 | Y27: 0 | Z27: 0 | AA27: 0 | AB27: 0
A28: Ring 1 | C28: 0 | D28: 0 | E28: 0 | F28: 0 | G28: 0 | H28: 0 | I28: 0 | J28: 0 | K28: 0 | L28: 0 | M28: 0 | N28: 0 | O28: 0 | P28: 0 | Q28: 0 | R28: 0 | S28: 0 | T28: 0 | U28: 0 | V28: 0 | W28: 0 | X28: 0 | Y28: 0 | Z28: 0 | AA28: 0 | AB28: 0
A29: Ring 2 | C29: 0 | D29: 0 | E29: 0 | F29: 0 | G29: 0 | H29: 0 | I29: 0 | J29: 0 | K29: 0 | L29: 0 | M29: 0 | N29: 0 | O29: 0 | P29: 0 | Q29: 0 | R29: 0 | S29: 0 | T29: 0 | U29: 0 | V29: 0 | W29: 0 | X29: 0 | Y29: 0 | Z29: 0 | AA29: 0 | AB29: 0
A31: Stat Name | B31: Stat ID | C31: Type | D31: Abbreviated Formula | E31: Value
A32: Spirit | B32: Spirit | C32: Primary | D32: 0 | E32: =F11 -> 10
A33: Faith Regeneration Increase | B33: FaithRegenerationIncrease | C33: Derived | D33: (Spirit * 0.03) | E33: =(F11 * 0.03) -> 0.3
A34: Attunement | B34: Attunement | C34: Primary | D34: 0 | E34: =F6 -> 10
A35: Endurance | B35: Endurance | C35: Primary | D35: 0 | E35: =F10 -> 10
A36: Guts Threshold Increase | B36: GutsThresholdIncrease | C36: Hidden | D36: (Endurance * 0.01) | E36: =(F10 * 0.01) -> 0.1
A37: Maximum Prospecting Fragility | B37: ProspectingFragilityMax | C37: Derived | D37: 100 | E37: =100 -> 100
A38: Shadow Resistance | B38: ShadowResistanceValue | C38: Hidden | D38: 0 | E38: =SUM(Y18:Y29) -> 0
A39: Size Modifier | B39: SizeModifier | C39: Hidden | E39: =
A40: Panic Rating Decay | B40: PanicDecay | C40: Derived | D40: -5 | E40: =-5 -> -5
A41: Spirit Resistance | B41: SpiritResistanceValue | C41: Hidden | D41: 0 | E41: =SUM(AA18:AA29) -> 0
A42: Spirit Resistance Multiplier | B42: SpiritResistanceMultiplier | C42: Derived | D42: 1 - SpiritResistanceValue | E42: =1 - E41 -> 1
A43: Vitality | B43: Vitality | C43: Primary | D43: 0 | E43: =F13 -> 10
...

Sheet Stat Analysis
A1: Name | B1: Stat ID | C1: Description | D1: Formula (abbreviated) | E1: Base Value (0) | F1: Primary Stat Dependencies | G1: Direct Stat Dependencies | H1: Full Stat Dependency Chain | I1: Base (10) | J1: Human (12) | K1: Minor Racial (13) | L1: Major Racial (14) | M1: Max Base (50) | N1: Max Human (52) | O1: Max Minor Racial (53) | P1: Max Major Racial (54) | Q1: Show at Char Creation | R1: Formula (raw) | S1: Type
A2: Arcane Resistance Multiplier | B2: ArcaneResistanceMultiplier | C2: Multiplier for arcane damage from resistance | D2: 1 - ArcaneResistanceValue | E2: 1 | G2: Arcane Resistance | H2: Arcane Resistance | I2: 1 | J2: 1 | K2: 1 | L2: 1 | M2: 1 | N2: 1 | O2: 1 | P2: 1 | Q2: Yes | R2: 1 - Ctx.GetOrCalculateStat(Stat.ArcaneResistanceValue) | S2: Derived
A3: Base Faith Regeneration | B3: BaseFaithRegeneration | C3: Base Faith Regeneration from Spirit and flat sources | D3: 10 | E3: 10 | I3: 10 | J3: 10 | K3: 10 | L3: 10 | M3: 10 | N3: 10 | O3: 10 | P3: 10 | Q3: Yes | R3: 10 | S3: Derived
A4: Base Health Regeneration | B4: BaseHealthRegeneration | C4: Base Health Regeneration from Vitality and flat sources | D4: MaxHP / 150 | E4: 33.333333 | F4: Vitality | G4: Maximum Health | H4: Base Maximum Health, Maximum Health, Maximum Health Increase | I4: 48 | J4: 51.253333 | K4: 52.92 | L4: 54.613333 | M4: 133.33333 | N4: 138.72 | O4: 141.45333 | P4: 144.21333 | Q4: Yes | R4: Ctx.GetOrCalculateStat(Stat.MaxHP) / 150 | S4: Derived
A5: Base Mana Regeneration | B5: BaseManaRegeneration | C5: Base Mana Regeneration from Spirit and flat sources | D5: MaxMana / 500 | E5: 10 | F5: Spirit | G5: Max Mana | H5: Base Maximum Mana, Max Mana, Maximum Mana Increase | I5: 14.4 | J5: 15.376 | K5: 15.876 | L5: 16.384 | M5: 40 | N5: 41.616 | O5: 42.436 | P5: 43.264 | Q5: Yes | R5: Ctx.GetOrCalculateStat(Stat.MaxMana) / 500 | S5: Derived
A6: Base Maximum Health | B6: BaseMaxHP | C6: Base Maximum Health from Vitality and flat sources | D6: 5000 + 100 * Vitality | E6: 5000 | F6: Vitality | I6: 6000 | J6: 6200 | K6: 6300 | L6: 6400 | M6: 10000 | N6: 10200 | O6: 10300 | P6: 10400 | Q6: Yes | R6: 5000 + 100 * Ctx.GetOrCalculateStat(Stat.Vitality) | S6: Derived
A7: Base Maximum Mana | B7: BaseMaxMana | C7: Base Maximum Mana from Spirit and flat sources | D7: 5000 + 100 * Spirit | E7: 5000 | F7: Spirit | I7: 6000 | J7: 6200 | K7: 6300 | L7: 6400 | M7: 10000 | N7: 10200 | O7: 10300 | P7: 10400 | Q7: Yes | R7: 5000 + 100 * Ctx.GetOrCalculateStat(Stat.Spirit) | S7: Derived
A8: Buff Duration | B8: BuffDurationMultiplier | C8: Increases the duration of Buffs you apply | D8: (1 + Conviction * 0.005) | E8: 1 | F8: Conviction | I8: 1.05 | J8: 1.06 | K8: 1.065 | L8: 1.07 | M8: 1.25 | N8: 1.26 | O8: 1.265 | P8: 1.27 | Q8: Yes | R8: (float) (1 + Ctx.GetOrCalculateStat(Stat.Conviction) * 0.005) | S8: Derived
A9: Buff Effect | B9: BuffEffectMultiplier | C9: Increases the numerical values of Buffs you apply | D9: (1 + Conviction * 0.005) | E9: 1 | F9: Conviction | I9: 1.05 | J9: 1.06 | K9: 1.065 | L9: 1.07 | M9: 1.25 | N9: 1.26 | O9: 1.265 | P9: 1.27 | Q9: Yes | R9: (float) (1 + Ctx.GetOrCalculateStat(Stat.Conviction) * 0.005) | S9: Derived
A10: Chaos Resistance Multiplier | B10: ChaosResistanceMultiplier | C10: Multiplier for chaos damage from resistance | D10: 1 - ChaosResistanceValue | E10: 1 | G10: Chaos Resistance | H10: Chaos Resistance | I10: 1 | J10: 1 | K10: 1 | L10: 1 | M10: 1 | N10: 1 | O10: 1 | P10: 1 | Q10: Yes | R10: 1 - Ctx.GetOrCalculateStat(Stat.ChaosResistanceValue) | S10: Derived
A11: Critical Hit Chance | B11: CriticalHitChance | C11: Fraction chance for critical hits | D11: (2 * (1 / (1 + Exp(-0.011 * CriticalHitRating))) - 1) | E11: 0.054945 | G11: Critical Hit Rating | H11: Critical Hit Rating | I11: 0.054945 | J11: 0.054945 | K11: 0.054945 | L11: 0.054945 | M11: 0.054945 | N11: 0.054945 | O11: 0.054945 | P11: 0.054945 | Q11: Yes | R11: (float) (2 * (1 / (1 + System.Math.Exp(-0.011 * Ctx.GetOrCalculateStat(Stat.CriticalHitRating)))) - 1) | S11: Derived
A12: Crushing Resistance Multiplier | B12: CrushingResistanceMultiplier | C12: Multiplier for crushing damage from resistance | D12: 1 - CrushingResistanceValue | E12: 1 | G12: Crushing Resistance | H12: Crushing Resistance | I12: 1 | J12: 1 | K12: 1 | L12: 1 | M12: 1 | N12: 1 | O12: 1 | P12: 1 | Q12: Yes | R12: 1 - Ctx.GetOrCalculateStat(Stat.CrushingResistanceValue) | S12: Derived
A13: Current Max Health | B13: MaxHPLimit | C13: Restricted Max HP for limitations like Wounds | D13: MaxHP | E13: 5000 | F13: Vitality | G13: Maximum Health | H13: Base Maximum Health, Maximum Health, Maximum Health Increase | I13: 7200 | J13: 7688 | K13: 7938 | L13: 8192 | M13: 20000 | N13: 20808 | O13: 21218 | P13: 21632 | Q13: Yes | R13: Ctx.GetOrCalculateStat(Stat.MaxHP) | S13: Derived
A14: Debuff Duration Multiplier | B14: DebuffDurationMultiplier | C14: Multiplier for duration of Debuffs applied to you | D14: 1 - DebuffDurationReduction | E14: 1 | F14: Endurance | G14: Debuff Duration Reduction | H14: Debuff Duration Reduction | I14: 0.95 | J14: 0.94 | K14: 0.935 | L14: 0.93 | M14: 0.75 | N14: 0.74 | O14: 0.735 | P14: 0.73 | Q14: Yes | R14: 1 - Ctx.GetOrCalculateStat(Stat.DebuffDurationReduction) | S14: Derived
A15: Debuff Duration Reduction | B15: DebuffDurationReduction | C15: Reduces the duration of Debuffs applied to you | D15: (Endurance * 0.005) | E15: 0 | F15: Endurance | I15: 0.05 | J15: 0.06 | K15: 0.065 | L15: 0.07 | M15: 0.25 | N15: 0.26 | O15: 0.265 | P15: 0.27 | Q15: Yes | R15: (float) (Ctx.GetOrCalculateStat(Stat.Endurance) * 0.005) | S15: Derived
A16: Detection Range | B16: DetectionRange | C16: Determines how far away you can see Stealthed enemies. | D16: (5 + Command * 0.75) | E16: 5 | F16: Command | I16: 12.5 | J16: 14 | K16: 14.75 | L16: 15.5 | M16: 42.5 | N16: 44 | O16: 44.75 | P16: 45.5 | Q16: Yes | R16: (float) (5 + Ctx.GetOrCalculateStat(Stat.Command) * 0.75) | S16: Derived
A17: Detection Regen | B17: DetectionRegen | C17: Regen to make Detection Resource work | D17: 100 | E17: 100 | I17: 100 | J17: 100 | K17: 100 | L17: 100 | M17: 100 | N17: 100 | O17: 100 | P17: 100 | Q17: Yes | R17: 100 | S17: Derived
A18: Earth Resistance Multiplier | B18: EarthResistanceMultiplier | C18: Multiplier for earth damage from resistance | D18: 1 - EarthResistanceValue | E18: 1 | G18: Earth Resistance | H18: Earth Resistance | I18: 1 | J18: 1 | K18: 1 | L18: 1 | M18: 1 | N18: 1 | O18: 1 | P18: 1 | Q18: Yes | R18: 1 - Ctx.GetOrCalculateStat(Stat.EarthResistanceValue) | S18: Derived
A19: Faith Regeneration Increase | B19: FaithRegenerationIncrease | C19: Multiplier on Base Faith Regeneration | D19: (Spirit * 0.03) | E19: 0 | F19: Spirit | I19: 0.3 | J19: 0.36 | K19: 0.39 | L19: 0.42 | M19: 1.5 | N19: 1.56 | O19: 1.59 | P19: 1.62 | Q19: Yes | R19: (float) (Ctx.GetOrCalculateStat(Stat.Spirit) * 0.03) | S19: Derived
A20: Fire Resistance Multiplier | B20: FireResistanceMultiplier | C20: Multiplier for fire damage from resistance | D20: 1 - FireResistanceValue | E20: 1 | G20: Fire Resistance | H20: Fire Resistance | I20: 1 | J20: 1 | K20: 1 | L20: 1 | M20: 1 | N20: 1 | O20: 1 | P20: 1 | Q20: Yes | R20: 1 - Ctx.GetOrCalculateStat(Stat.FireResistanceValue) | S20: Derived
A21: Focus Charger Regen | B21: FocusChargerRegen | C21: Amount to increase focus charger bar per tick | D21: 20 | E21: 20 | I21: 20 | J21: 20 | K21: 20 | L21: 20 | M21: 20 | N21: 20 | O21: 20 | P21: 20 | Q21: Yes | R21: 20 | S21: Derived
A22: Healing Multiplier | B22: BaseHealingMultiplier | C22: Increases Healing done by your abilities | D22: (1 + Conviction * 0.01) | E22: 1 | F22: Conviction | I22: 1.1 | J22: 1.12 | K22: 1.13 | L22: 1.14 | M22: 1.5 | N22: 1.52 | O22: 1.53 | P22: 1.54 | Q22: Yes | R22: (float) (1 + Ctx.GetOrCalculateStat(Stat.Conviction) * 0.01) | S22: Derived
A23: Health Regeneration | B23: CombinedHealthRegeneration | C23: Rate at which combined health regenerates over time. | D23: HealthRegeneration | E23: 33.333333 | F23: Vitality | G23: Health Regeneration | H23: Base Health Regeneration, Base Maximum Health, Health Regeneration, Health Regeneration Increase, Maximum Health, Maximum Health Increase | I23: 57.6 | J23: 63.554133 | K23: 66.6792 | L23: 69.905067 | M23: 266.66667 | N23: 282.9888 | O23: 291.39387 | P23: 299.96373 | Q23: Yes | R23: Ctx.GetOrCalculateStat(Stat.HealthRegeneration) | S23: Derived
A24: Health Regeneration | B24: HealthRegeneration | C24: Health regenerated per second while out of combat. | D24: (BaseHealthRegeneration * (1 + HealthRegenerationIncrease)) | E24: 33.333333 | F24: Vitality | G24: Base Health Regeneration, Health Regeneration Increase | H24: Base Health Regeneration, Base Maximum Health, Health Regeneration Increase, Maximum Health, Maximum Health Increase | I24: 57.6 | J24: 63.554133 | K24: 66.6792 | L24: 69.905067 | M24: 266.66667 | N24: 282.9888 | O24: 291.39387 | P24: 299.96373 | Q24: Yes | R24: (float) (Ctx.GetOrCalculateStat(Stat.BaseHealthRegeneration) * (1 + Ctx.GetOrCalculateStat(Stat.HealthRegenerationIncrease))) | S24: Derived
A25: Health Regeneration Increase | B25: HealthRegenerationIncrease | C25: Multiplier on Base Health Regeneration | D25: (Vitality * 0.02) | E25: 0 | F25: Vitality | I25: 0.2 | J25: 0.24 | K25: 0.26 | L25: 0.28 | M25: 1 | N25: 1.04 | O25: 1.06 | P25: 1.08 | Q25: Yes | R25: (float) (Ctx.GetOrCalculateStat(Stat.Vitality) * 0.02) | S25: Derived
A26: Lightning Resistance Multiplier | B26: LightningResistanceMultiplier | C26: Multiplier for lightning damage from resistance | D26: 1 - LightningResistanceValue | E26: 1 | G26: Lightning Resistance | H26: Lightning Resistance | I26: 1 | J26: 1 | K26: 1 | L26: 1 | M26: 1 | N26: 1 | O26: 1 | P26: 1 | Q26: Yes | R26: 1 - Ctx.GetOrCalculateStat(Stat.LightningResistanceValue) | S26: Derived
A27: Magic Armor Multiplier | B27: MagicArmorMultiplier | C27: Multiplier for magic damage from armor | D27: 1 - (0.003 * MagicArmorRating) / (1 + 0.003 * MagicArmorRating) | E27: 1 | G27: Magic Armor Rating | H27: Magic Armor Rating | I27: 1 | J27: 1 | K27: 1 | L27: 1 | M27: 1 | N27: 1 | O27: 1 | P27: 1 | Q27: Yes | R27: 1 - (0.003f * Ctx.GetOrCalculateStat(Stat.MagicArmorRating)) / (1 + 0.003f * Ctx.GetOrCalculateStat(Stat.MagicArmorRating)) | S27: Derived
A28: Mana Regeneration Increase | B28: ManaRegenerationIncrease | C28: Multiplier on Base Mana Regeneration | D28: (Spirit * 0.02) | E28: 0 | F28: Spirit | I28: 0.2 | J28: 0.24 | K28: 0.26 | L28: 0.28 | M28: 1 | N28: 1.04 | O28: 1.06 | P28: 1.08 | Q28: Yes | R28: (float) (Ctx.GetOrCalculateStat(Stat.Spirit) * 0.02) | S28: Derived
A29: Maximum Combined Health | B29: MaxCombinedHealth | C29: Maximum HP + maximum shield | D29: MaxHP + MaxShield | E29: 7500 | F29: Vitality | G29: Maximum Health, Maximum Shield | H29: Base Maximum Health, Maximum Health, Maximum Health Increase, Maximum Shield | I29: 10800 | J29: 11532 | K29: 11907 | L29: 12288 | M29: 30000 | N29: 31212 | O29: 31827 | P29: 32448 | Q29: Yes | R29: Ctx.GetOrCalculateStat(Stat.MaxHP) + Ctx.GetOrCalculateStat(Stat.MaxShield) | S29: Derived
A30: Maximum Health | B30: MaxHP | C30: Maximum Health value | D30: (BaseMaxHP * (1 + MaxHPIncrease)) | E30: 5000 | F30: Vitality | G30: Base Maximum Health, Maximum Health Increase | H30: Base Maximum Health, Maximum Health Increase | I30: 7200 | J30: 7688 | K30: 7938 | L30: 8192 | M30: 20000 | N30: 20808 | O30: 21218 | P30: 21632 | Q30: Yes | R30: (float) (Ctx.GetOrCalculateStat(Stat.BaseMaxHP) * (1 + Ctx.GetOrCalculateStat(Stat.MaxHPIncrease))) | S30: Derived
A31: Maximum Health Increase | B31: MaxHPIncrease | C31: Multiplier on Base Maximum Health | D31: (Vitality * 0.02) | E31: 0 | F31: Vitality | I31: 0.2 | J31: 0.24 | K31: 0.26 | L31: 0.28 | M31: 1 | N31: 1.04 | O31: 1.06 | P31: 1.08 | Q31: Yes | R31: (float) (Ctx.GetOrCalculateStat(Stat.Vitality) * 0.02) | S31: Derived
A32: Maximum Mana Increase | B32: MaxManaIncrease | C32: Multiplier on Base Maximum Mana | D32: (Spirit * 0.02) | E32: 0 | F32: Spirit | I32: 0.2 | J32: 0.24 | K32: 0.26 | L32: 0.28 | M32: 1 | N32: 1.04 | O32: 1.06 | P32: 1.08 | Q32: Yes | R32: (float) (Ctx.GetOrCalculateStat(Stat.Spirit) * 0.02) | S32: Derived
A33: Maximum Panic Rating | B33: MaxPanic | C33: The maximum amount of Panic you can sustain before becoming vulnerable to Terror effects. | D33: 1000 | E33: 1000 | I33: 1000 | J33: 1000 | K33: 1000 | L33: 1000 | M33: 1000 | N33: 1000 | O33: 1000 | P33: 1000 | Q33: Yes | R33: 1000 | S33: Derived
A34: Maximum Prospecting Excavation | B34: ProspectingExcavationMax | C34: Maximum excavation of prospecting resource | D34: 100 | E34: 100 | I34: 100 | J34: 100 | K34: 100 | L34: 100 | M34: 100 | N34: 100 | O34: 100 | P34: 100 | Q34: Yes | R34: 100 | S34: Derived
A35: Maximum Prospecting Fragility | B35: ProspectingFragilityMax | C35: Maximum fragility of prospecting resource | D35: 100 | E35: 100 | I35: 100 | J35: 100 | K35: 100 | L35: 100 | M35: 100 | N35: 100 | O35: 100 | P35: 100 | Q35: Yes | R35: 100 | S35: Derived
A36: Maximum Shield | B36: MaxShield | C36: Increases the character's maximum shield value. | D36: MaxHP / 2 | E36: 2500 | F36: Vitality | G36: Maximum Health | H36: Base Maximum Health, Maximum Health, Maximum Health Increase | I36: 3600 | J36: 3844 | K36: 3969 | L36: 4096 | M36: 10000 | N36: 10404 | O36: 10609 | P36: 10816 | Q36: Yes | R36: Ctx.GetOrCalculateStat(Stat.MaxHP) / 2 | S36: Derived
A37: Mind Resistance Multiplier | B37: MindResistanceMultiplier | C37: Multiplier for mind damage from resistance | D37: 1 - MindResistanceValue | E37: 1 | G37: Mind Resistance | H37: Mind Resistance | I37: 1 | J37: 1 | K37: 1 | L37: 1 | M37: 1 | N37: 1 | O37: 1 | P37: 1 | Q37: Yes | R37: 1 - Ctx.GetOrCalculateStat(Stat.MindResistanceValue) | S37: Derived
A38: Movement Speed | B38: MaxMoveSpeed | C38: Increases the maximum movement speed of the character. | D38: 11 | E38: 11 | I38: 11 | J38: 11 | K38: 11 | L38: 11 | M38: 11 | N38: 11 | O38: 11 | P38: 11 | Q38: Yes | R38: 11 | S38: Derived
A39: Panic Multiplier | B39: BasePanicMultiplier | C39: Increases Panic inflicted by your abilities | D39: (1 + Command * 0.01) | E39: 1 | F39: Command | I39: 1.1 | J39: 1.12 | K39: 1.13 | L39: 1.14 | M39: 1.5 | N39: 1.52 | O39: 1.53 | P39: 1.54 | Q39: Yes | R39: (float) (1 + Ctx.GetOrCalculateStat(Stat.Command) * 0.01) | S39: Derived
A40: Panic Rating Decay | B40: PanicDecay | C40: Increase the rate at which accumulated Panic is decreased. | D40: -5 | E40: -5 | I40: -5 | J40: -5 | K40: -5 | L40: -5 | M40: -5 | N40: -5 | O40: -5 | P40: -5 | Q40: Yes | R40: -5 | S40: Derived
...
